Internal Server Error: /reset/
Traceback (most recent call last):
  File "/home/ruben/Documents/cacciacapitale/env/lib/python3.8/site-packages/django/core/handlers/exception.py", line 34, in inner
    response = get_response(request)
  File "/home/ruben/Documents/cacciacapitale/env/lib/python3.8/site-packages/django/core/handlers/base.py", line 115, in _get_response
    response = self.process_exception_by_middleware(e, request)
  File "/home/ruben/Documents/cacciacapitale/env/lib/python3.8/site-packages/django/core/handlers/base.py", line 113, in _get_response
    response = wrapped_callback(request, *callback_args, **callback_kwargs)
  File "/home/ruben/Documents/cacciacapitale/env/lib/python3.8/site-packages/django/contrib/auth/decorators.py", line 21, in _wrapped_view
    return view_func(request, *args, **kwargs)
  File "/home/ruben/Documents/cacciacapitale/cacciacapitale_bot/bot_site/views.py", line 28, in reset
    logging.error("STO RESETTANDO")
  File "/usr/lib/python3.8/logging/__init__.py", line 2049, in error
    root.error(msg, *args, **kwargs)
  File "/usr/lib/python3.8/logging/__init__.py", line 1475, in error
    self._log(ERROR, msg, args, **kwargs)
  File "/usr/lib/python3.8/logging/__init__.py", line 1589, in _log
    self.handle(record)
  File "/usr/lib/python3.8/logging/__init__.py", line 1599, in handle
    self.callHandlers(record)
  File "/usr/lib/python3.8/logging/__init__.py", line 1661, in callHandlers
    hdlr.handle(record)
  File "/usr/lib/python3.8/logging/__init__.py", line 954, in handle
    self.emit(record)
  File "/home/ruben/Documents/cacciacapitale/cacciacapitale_bot/Bot/apps.py", line 29, in emit
    self.bot.send_message(chat_id=id, text=self.format(record))
  File "/home/ruben/Documents/cacciacapitale/env/lib/python3.8/site-packages/telegram/bot.py", line 66, in decorator
    result = func(self, *args, **kwargs)
  File "/home/ruben/Documents/cacciacapitale/env/lib/python3.8/site-packages/telegram/bot.py", line 256, in send_message
    return self._message(url, data, disable_notification=disable_notification,
  File "/home/ruben/Documents/cacciacapitale/env/lib/python3.8/site-packages/telegram/bot.py", line 123, in _message
    result = self._request.post(url, data, timeout=timeout)
  File "/home/ruben/Documents/cacciacapitale/env/lib/python3.8/site-packages/telegram/utils/request.py", line 324, in post
    result = self._request_wrapper('POST', url,
  File "/home/ruben/Documents/cacciacapitale/env/lib/python3.8/site-packages/telegram/utils/request.py", line 238, in _request_wrapper
    raise BadRequest(message)
telegram.error.BadRequest: Chat not found